Workbook

Sheet Pública
B2: Lo que dicen los estudiantes
B3: ="Encuesta de personería estudiantil · "&COUNTA(Avanzada!$A$5:$A$108)&" estudiantes de "&MIN(Avanzada!$C$5:$C$108)&".° a "&MAX(Avanzada!$C$5:$C$108)&".° grado" -> Encuesta de personería estudiantil · 104 estudiantes de 6.° a 11.° grado
B7: =COUNTA(Avanzada!$A$5:$A$108) -> 104 | E7: =General!H45 -> 0.66346154 | H7: =General!C109/(General!C109+General!D109) -> 0.93269231 | K7: =General!D99 -> 0.45192308
B8: estudiantes encuestados | E8: se muestra dispuesto a votar | H8: respondió la pregunta abierta P8 | K8: propone temas sociales y culturales
B10: =ROUND(General!H45*100,0)&"% está dispuesto a votar" -> 66% está dispuesto a votar | H10: Las propuestas de los estudiantes
B11: Respuestas a P2 (escala 1 a 5) · % de los encuestados | H11: Temas mencionados · % de estudiantes (pueden mencionar varios)
B29: ="Hay una brecha de escucha: solo "&ROUND(General!E53*100,0)&"% siente que su representante lo escucha" -> Hay una brecha de escucha: solo 33% siente que su representante lo escucha
B30: Opinión sobre 4 aspectos de la vida estudiantil · % de los encuestados · en desacuerdo = 1–2 · neutral = 3 · de acuerdo = 4–5
B49: ="Fuente: encuesta aplicada a "&COUNTA(Avanzada!$A$5:$A$108)&" estudiantes. Porcentajes sobre el total de encuestados; las cifras describen a quienes respondieron. Detalle completo y verificable en las hojas General y Avanzada." -> Fuente: encuesta aplicada a 104 estudiantes. Porcentajes sobre el total de encuestados; las cifras describen a quienes respondieron. Detalle completo y verificable en las hojas General y Avanzada.

Sheet General
B2: Resultados de la encuesta · Personería estudiantil
B3: ="Análisis general · "&COUNTA(Avanzada!$A$5:$A$108)&" estudiantes encuestados de "&MIN(Avanzada!$C$5:$C$108)&".° a "&MAX(Avanzada!$C$5:$C$108)&".° grado" -> Análisis general · 104 estudiantes encuestados de 6.° a 11.° grado
B5: • Escala P2 a P6: 1 a 5. «De acuerdo» = respuestas 4 y 5 · «Neutral» = 3 · «En desacuerdo» = 1 y 2.
B6: • Porcentajes calculados sobre el total de encuestados. ± = margen de error al 95 % (supone muestra aleatoria simple).
B7: • Todas las cifras son fórmulas calculadas desde la hoja Avanzada, que contiene las respuestas individuales.
B9: 1 Participación por grado
B10: Grado | C10: Encuestas | D10: % del total
B11: 6 | C11: =COUNTIF(Avanzada!$C$5:$C$108,B11) -> 9 | D11: =C11/C$17 -> 0.086538462
B12: 7 | C12: =COUNTIF(Avanzada!$C$5:$C$108,B12) -> 10 | D12: =C12/C$17 -> 0.096153846
B13: 8 | C13: =COUNTIF(Avanzada!$C$5:$C$108,B13) -> 23 | D13: =C13/C$17 -> 0.22115385
B14: 9 | C14: =COUNTIF(Avanzada!$C$5:$C$108,B14) -> 27 | D14: =C14/C$17 -> 0.25961538
B15: 10 | C15: =COUNTIF(Avanzada!$C$5:$C$108,B15) -> 18 | D15: =C15/C$17 -> 0.17307692
B16: 11 | C16: =COUNTIF(Avanzada!$C$5:$C$108,B16) -> 17 | D16: =C16/C$17 -> 0.16346154
B17: Total | C17: =SUM(C11:C16) -> 104 | D17: =SUM(D11:D16) -> 1
B19: En rojo: grados con menos de 15 respuestas. Interpretar sus resultados con cautela.
B26: 2 Distribución de respuestas (P2 a P6)
B27: Cantidad de respuestas | C27: 1 | D27: 2 | E27: 3 | F27: 4 | G27: 5 | H27: Total
B28: P2 · Disposición a votar | C28: =COUNTIF(Avanzada!$D$5:$D$108,1) -> 9 | D28: =COUNTIF(Avanzada!$D$5:$D$108,2) -> 9 | E28: =COUNTIF(Avanzada!$D$5:$D$108,3) -> 17 | F28: =COUNTIF(Avanzada!$D$5:$D$108,4) -> 40 | G28: =COUNTIF(Avanzada!$D$5:$D$108,5) -> 29 | H28: =SUM(C28:G28) -> 104
B29: P3 · Escuchado por su representante | C29: =COUNTIF(Avanzada!$E$5:$E$108,1) -> 30 | D29: =COUNTIF(Avanzada!$E$5:$E$108,2) -> 21 | E29: =COUNTIF(Avanzada!$E$5:$E$108,3) -> 19 | F29: =COUNTIF(Avanzada!$E$5:$E$108,4) -> 22 | G29: =COUNTIF(Avanzada!$E$5:$E$108,5) -> 12 | H29: =SUM(C29:G29) -> 104
B30: P4 · Escuchado por la institución | C30: =COUNTIF(Avanzada!$F$5:$F$108,1) -> 23 | D30: =COUNTIF(Avanzada!$F$5:$F$108,2) -> 23 | E30: =COUNTIF(Avanzada!$F$5:$F$108,3) -> 22 | F30: =COUNTIF(Avanzada!$F$5:$F$108,4) -> 27 | G30: =COUNTIF(Avanzada!$F$5:$F$108,5) -> 9 | H30: =SUM(C30:G30) -> 104
B31: P5 · Facilidad para dar sugerencias | C31: =COUNTIF(Avanzada!$G$5:$G$108,1) -> 21 | D31: =COUNTIF(Avanzada!$G$5:$G$108,2) -> 18 | E31: =COUNTIF(Avanzada!$G$5:$G$108,3) -> 37 | F31: =COUNTIF(Avanzada!$G$5:$G$108,4) -> 16 | G31: =COUNTIF(Avanzada!$G$5:$G$108,5) -> 12 | H31: =SUM(C31:G31) -> 104
B32: P6 · Satisfacción con actividades | C32: =COUNTIF(Avanzada!$H$5:$H$108,1) -> 11 | D32: =COUNTIF(Avanzada!$H$5:$H$108,2) -> 20 | E32: =COUNTIF(Avanzada!$H$5:$H$108,3) -> 37 | F32: =COUNTIF(Avanzada!$H$5:$H$108,4) -> 25 | G32: =COUNTIF(Avanzada!$H$5:$H$108,5) -> 11 | H32: =SUM(C32:G32) -> 104
B34: Porcentaje de respuestas | C34: 1 | D34: 2 | E34: 3 | F34: 4 | G34: 5 | H34: Total
B35: P2 · Disposición a votar | C35: =C28/$H28 -> 0.086538462 | D35: =D28/$H28 -> 0.086538462 | E35: =E28/$H28 -> 0.16346154 | F35: =F28/$H28 -> 0.38461538 | G35: =G28/$H28 -> 0.27884615 | H35: =SUM(C35:G35) -> 1
B36: P3 · Escuchado por su representante | C36: =C29/$H29 -> 0.28846154 | D36: =D29/$H29 -> 0.20192308 | E36: =E29/$H29 -> 0.18269231 | F36: =F29/$H29 -> 0.21153846 | G36: =G29/$H29 -> 0.11538462 | H36: =SUM(C36:G36) -> 1
B37: P4 · Escuchado por la institución | C37: =C30/$H30 -> 0.22115385 | D37: =D30/$H30 -> 0.22115385 | E37: =E30/$H30 -> 0.21153846 | F37: =F30/$H30 -> 0.25961538 | G37: =G30/$H30 -> 0.086538462 | H37: =SUM(C37:G37) -> 1
B38: P5 · Facilidad para dar sugerencias | C38: =C31/$H31 -> 0.20192308 | D38: =D31/$H31 -> 0.17307692 | E38: =E31/$H31 -> 0.35576923 | F38: =F31/$H31 -> 0.15384615 | G38: =G31/$H31 -> 0.11538462 | H38: =SUM(C38:G38) -> 1
B39: P6 · Satisfacción con actividades | C39: =C32/$H32 -> 0.10576923 | D39: =D32/$H32 -> 0.19230769 | E39: =E32/$H32 -> 0.35576923 | F39: =F32/$H32 -> 0.24038462 | G39: =G32/$H32 -> 0.10576923 | H39: =SUM(C39:G39) -> 1
B43: 3 Indicadores estadísticos
B44: Pregunta | C44: N | D44: Media | E44: Mediana | F44: Moda | G44: Desv. estándar | H44: % de acuerdo (4–5) | I44: ± margen de error
B45: P2 · Disposición a votar | C45: =COUNT(Avanzada!$D$5:$D$108) -> 104 | D45: =AVERAGE(Avanzada!$D$5:$D$108) -> 3.6826923 | E45: =MEDIAN(Avanzada!$D$5:$D$108) -> 4 | F45: =MODE(Avanzada!$D$5:$D$108) -> 4 | G45: =STDEV(Avanzada!$D$5:$D$108) -> 1.216907 | H45: =COUNTIF(Avanzada!$D$5:$D$108,">=4")/C45 -> 0.66346154 | I45: =1.96*SQRT(H45*(1-H45)/C45) -> 0.090816473
B46: P3 · Escuchado por su representante | C46: =COUNT(Avanzada!$E$5:$E$108) -> 104 | D46: =AVERAGE(Avanzada!$E$5:$E$108) -> 2.6634615 | E46: =MEDIAN(Avanzada!$E$5:$E$108) -> 3 | F46: =MODE(Avanzada!$E$5:$E$108) -> 1 | G46: =STDEV(Avanzada!$E$5:$E$108) -> 1.3907501 | H46: =COUNTIF(Avanzada!$E$5:$E$108,">=4")/C46 -> 0.32692308 | I46: =1.96*SQRT(H46*(1-H46)/C46) -> 0.09015598
B47: P4 · Escuchado por la institución | C47: =COUNT(Avanzada!$F$5:$F$108) -> 104 | D47: =AVERAGE(Avanzada!$F$5:$F$108) -> 2.7692308 | E47: =MEDIAN(Avanzada!$F$5:$F$108) -> 3 | F47: =MODE(Avanzada!$F$5:$F$108) -> 4 | G47: =STDEV(Avanzada!$F$5:$F$108) -> 1.2939799 | H47: =COUNTIF(Avanzada!$F$5:$F$108,">=4")/C47 -> 0.34615385 | I47: =1.96*SQRT(H47*(1-H47)/C47) -> 0.091434853
B48: P5 · Facilidad para dar sugerencias | C48: =COUNT(Avanzada!$G$5:$G$108) -> 104 | D48: =AVERAGE(Avanzada!$G$5:$G$108) -> 2.8076923 | E48: =MEDIAN(Avanzada!$G$5:$G$108) -> 3 | F48: =MODE(Avanzada!$G$5:$G$108) -> 3 | G48: =STDEV(Avanzada!$G$5:$G$108) -> 1.2547148 | H48: =COUNTIF(Avanzada!$G$5:$G$108,">=4")/C48 -> 0.26923077 | I48: =1.96*SQRT(H48*(1-H48)/C48) -> 0.085249507
B49: P6 · Satisfacción con actividades | C49: =COUNT(Avanzada!$H$5:$H$108) -> 104 | D49: =AVERAGE(Avanzada!$H$5:$H$108) -> 3.0480769 | E49: =MEDIAN(Avanzada!$H$5:$H$108) -> 3 | F49: =MODE(Avanzada!$H$5:$H$108) -> 3 | G49: =STDEV(Avanzada!$H$5:$H$108) -> 1.1353098 | H49: =COUNTIF(Avanzada!$H$5:$H$108,">=4")/C49 -> 0.34615385 | I49: =1.96*SQRT(H49*(1-H49)/C49) -> 0.091434853
B51: Resumen en tres niveles | C51: % En desacuerdo (1–2) | D51: % Neutral (3) | E51: % De acuerdo (4–5)
B52: P2 · Disposición a votar | C52: =COUNTIF(Avanzada!$D$5:$D$108,"<=2")/C45 -> 0.17307692 | D52: =COUNTIF(Avanzada!$D$5:$D$108,3)/C45 -> 0.16346154 | E52: =COUNTIF(Avanzada!$D$5:$D$108,">=4")/C45 -> 0.66346154
B53: P3 · Escuchado por su representante | C53: =COUNTIF(Avanzada!$E$5:$E$108,"<=2")/C46 -> 0.49038462 | D53: =COUNTIF(Avanzada!$E$5:$E$108,3)/C46 -> 0.18269231 | E53: =COUNTIF(Avanzada!$E$5:$E$108,">=4")/C46 -> 0.32692308
B54: P4 · Escuchado por la institución | C54: =COUNTIF(Avanzada!$F$5:$F$108,"<=2")/C47 -> 0.44230769 | D54: =COUNTIF(Avanzada!$F$5:$F$108,3)/C47 -> 0.21153846 | E54: =COUNTIF(Avanzada!$F$5:$F$108,">=4")/C47 -> 0.34615385
B55: P5 · Facilidad para dar sugerencias | C55: =COUNTIF(Avanzada!$G$5:$G$108,"<=2")/C48 -> 0.375 | D55: =COUNTIF(Avanzada!$G$5:$G$108,3)/C48 -> 0.35576923 | E55: =COUNTIF(Avanzada!$G$5:$G$108,">=4")/C48 -> 0.26923077
...

Sheet Avanzada
A1: Respuestas individuales de la encuesta
A2: =COUNTA(A5:A108)&" registros · datos originales sin modificar · use los filtros de cada columna para ordenar, buscar y verificar" -> 104 registros · datos originales sin modificar · use los filtros de cada columna para ordenar, buscar y verificar
A3: IDENTIFICACIÓN | D3: ESCALA 1 A 5 | I3: SÍ / NO | J3: ABIERTAS | L3: CATEGORÍAS DE PROPUESTA | R3: ¿RESPONDIÓ? | T3: CONTROL DE CAPTURA
A4: N.º encuesta | B4: Archivo | C4: Grado | D4: P2 Disposición a votar | E4: P3 Escuchado por su representante | F4: P4 Escuchado por la institución | G4: P5 Facilidad para dar sugerencias | H4: P6 Satisfacción con actividades | I4: P7 ¿Espacio adecuado? | J4: P8 Respuesta abierta (texto) | K4: P9 Respuesta abierta (texto) | L4: Académico | M4: Social / Cultural | N4: Infraestructura | O4: Ambiental | P4: Salud mental | Q4: Convivencial | R4: P8 respondida | S4: P9 respondida | T4: Estado de captura | U4: Observaciones de captura (OCR)
A5: 22 | B5: Encuesta.tiff | C5: 10 | D5: 4 | E5: 2 | F5: 2 | G5: 2 | H5: 4 | I5: No | L5: FALSE | M5: FALSE | N5: FALSE | O5: FALSE | P5: FALSE | Q5: FALSE | R5: TRUE | S5: FALSE | T5: REVISAR | U5: numero_encuesta:?; grado:?; p2:?; p3:?; p4:?; p5:?; p6:?
A6: 21 | B6: Encuesta1.tiff | C6: 10 | D6: 4 | E6: 1 | F6: 4 | G6: 3 | H6: 3 | I6: No | L6: FALSE | M6: TRUE | N6: FALSE | O6: FALSE | P6: FALSE | Q6: TRUE | R6: FALSE | S6: FALSE | T6: REVISAR | U6: numero_encuesta:?; grado:?; p2:?; p3:?; p4:?; p5:?; p6:?
A7: 38 | B7: Encuesta10.tiff | C7: 9 | D7: 5 | E7: 3 | F7: 2 | G7: 4 | H7: 4 | I7: Si | L7: FALSE | M7: FALSE | N7: FALSE | O7: FALSE | P7: FALSE | Q7: FALSE | R7: TRUE | S7: FALSE | T7: REVISAR | U7: numero_encuesta:?; grado:?; p2:?; p3:?; p4:?; p5:?; p6:?; p7:?
A8: 36 | B8: Encuesta11.tiff | C8: 9 | D8: 4 | E8: 5 | F8: 3 | G8: 1 | H8: 1 | I8: No | L8: FALSE | M8: FALSE | N8: FALSE | O8: FALSE | P8: FALSE | Q8: FALSE | R8: TRUE | S8: FALSE | T8: REVISAR | U8: numero_encuesta:?; grado:?; p2:?; p3:?; p4:?; p5:?; p6:?
A9: 34 | B9: Encuesta12.tiff | C9: 9 | D9: 5 | E9: 1 | F9: 1 | G9: 3 | H9: 4 | I9: Si | L9: FALSE | M9: TRUE | N9: TRUE | O9: FALSE | P9: FALSE | Q9: FALSE | R9: TRUE | S9: TRUE | T9: REVISAR | U9: grado:?; p2:?; p3:?; p4:?; p5:?; p6:?; p7:?
A10: 35 | B10: Encuesta13.tiff | C10: 9 | D10: 4 | E10: 3 | F10: 1 | G10: 4 | H10: 3 | I10: Si | L10: FALSE | M10: TRUE | N10: FALSE | O10: FALSE | P10: FALSE | Q10: TRUE | R10: TRUE | S10: TRUE | T10: REVISAR | U10: numero_encuesta:?; grado:?; p2:?; p3:?; p4:?; p5:?; p6:?; p7:?
A11: 33 | B11: Encuesta14.tiff | C11: 10 | D11: 4 | E11: 2 | F11: 4 | G11: 3 | H11: 3 | I11: No | L11: FALSE | M11: FALSE | N11: FALSE | O11: FALSE | P11: FALSE | Q11: FALSE | R11: TRUE | S11: FALSE | T11: REVISAR | U11: grado:?; p2:?; p3:?; p4:?; p5:?; p6:?
A12: 32 | B12: Encuesta15.tiff | C12: 10 | D12: 5 | E12: 2 | F12: 3 | G12: 3 | H12: 3 | I12: Si | L12: FALSE | M12: FALSE | N12: FALSE | O12: FALSE | P12: FALSE | Q12: FALSE | R12: TRUE | S12: FALSE | T12: REVISAR | U12: numero_encuesta:?; grado:?; p2:?; p3:?; p4:?; p5:?; p6:?; p7:?
A13: 31 | B13: Encuesta16.tiff | C13: 9 | D13: 4 | E13: 2 | F13: 2 | G13: 3 | H13: 4 | I13: Si | L13: FALSE | M13: FALSE | N13: FALSE | O13: FALSE | P13: FALSE | Q13: FALSE | R13: TRUE | S13: FALSE | T13: REVISAR | U13: numero_encuesta:?; grado:?; p2:?; p3:?; p4:?; p5:?; p6:?; p7:?
A14: 2 | B14: Encuesta17.tiff | C14: 11 | D14: 5 | E14: 4 | F14: 5 | G14: 5 | H14: 5 | I14: Si | L14: TRUE | M14: FALSE | N14: FALSE | O14: FALSE | P14: FALSE | Q14: FALSE | R14: FALSE | S14: TRUE | T14: REVISAR | U14: numero_encuesta:?; grado:?; p2:?; p3:?; p4:?; p5:?; p6:?; p7:?
A15: 1 | B15: Encuesta18.tiff | C15: 10 | D15: 5 | E15: 4 | F15: 5 | G15: 5 | H15: 5 | I15: Si | L15: TRUE | M15: FALSE | N15: FALSE | O15: FALSE | P15: FALSE | Q15: TRUE | R15: TRUE | S15: TRUE | T15: REVISAR | U15: numero_encuesta:?; grado:?; p2:?; p3:?; p4:?; p5:?; p6:?; p7:?
A16: 4 | B16: Encuesta19.tiff | C16: 9 | D16: 5 | E16: 1 | F16: 3 | G16: 4 | H16: 1 | I16: No | L16: TRUE | M16: FALSE | N16: FALSE | O16: TRUE | P16: FALSE | Q16: TRUE | R16: TRUE | S16: TRUE | T16: REVISAR | U16: numero_encuesta:?; grado:?; p2:?; p3:?; p4:?; p5:?; p6:?
... A108: 73 | B108: imga.tiff | C108: 8 | D108: 2 | E108: 1 | F108: 3 | G108: 1 | H108: 3 | I108: Si | L108: FALSE | M108: FALSE | N108: TRUE | O108: FALSE | P108: FALSE | Q108: FALSE | R108: TRUE | S108: TRUE | T108: REVISAR | U108: numero_encuesta:?; grado:?; p2:?; p3:?; p4:?; p5:?; p6:?
